Workbook
Name chartTableData: 'RACE.MI'!$A$12:$E$17
Name chartTableHeader: 'RACE.MI'!$A$11:$E$11
Name chartTableName: 'RACE.MI'!$A$10:$A$10
Name chartTableTotal: 'RACE.MI'!$B$10:$B$10
Name CLS: 'RACE.MI'!$B$30:$B$1302
Name DAT: 'RACE.MI'!$A$30:$A$1302
Name filterValues: 'RACE.MI'!$A$4:$A$7
Name FLOW: 'RACE.MI'!$M$30:$M$1302
Name HIG: 'RACE.MI'!$G$30:$G$1302
Name HLR: 'RACE.MI'!$K$30:$K$1302
Name LOW: 'RACE.MI'!$F$30:$F$1302
Name NET: 'RACE.MI'!$C$30:$C$1302
Name OCR: 'RACE.MI'!$J$30:$J$1302
Name OPN: 'RACE.MI'!$E$30:$E$1302
Name PCC: 'RACE.MI'!$D$30:$D$1302
Name PCV: 'RACE.MI'!$L$30:$L$1302
Name phTableData: 'RACE.MI'!$A$30:$N$1302
Name phTableHeader: 'RACE.MI'!$A$29:$N$29
Name phTableName: 'RACE.MI'!$A$28:$A$28
Name sheetHeader: 'RACE.MI'!$A$1:$A$1
Name statPriceChangeTableData: 'RACE.MI'!$K$22:$M$24
Name statPriceChangeTableHeader: 'RACE.MI'!$K$21:$M$21
Name statPriceTableData: 'RACE.MI'!$A$22:$C$25
Name statPriceTableHeader: 'RACE.MI'!$A$21:$C$21
Name statTableName: 'RACE.MI'!$A$20:$A$20
Name statTurnoverTableData: 'RACE.MI'!$N$22:$P$24
Name statTurnoverTableHeader: 'RACE.MI'!$N$21:$P$21
Name statUpDownTableData: 'RACE.MI'!$I$22:$J$24
Name statUpDownTableHeader: 'RACE.MI'!$I$21:$J$21
Name statVolumeTableData: 'RACE.MI'!$D$22:$H$24
Name statVolumeTableHeader: 'RACE.MI'!$D$21:$H$21
Name TRDPRC_1: 'RACE.MI'!$N$30:$N$1302
Name TRNOVR_UNS: 'RACE.MI'!$I$30:$I$1302
Name VOL: 'RACE.MI'!$H$30:$H$1302

Sheet RACE.MI
A1: Ferrari NV | Price History 13-Feb-2026 09:54
A4: RACE.MI
A5: Interval: Daily
A6: History Period: 01-Jan-2019 - 31-Dec-2023
A7: Currency Conversion: EUR
A10: VAP: Total | B10: 512683371
A11: Price | B11: Volume | C11: %Volume | D11: Count | E11: %Count
A12: 300.0000 - 350.0000 | B12: 13284020 | C12: 0.025910768 | D12: 40 | E12: 0.031421838
A13: 250.0000 - 300.0000 | B13: 46732319 | C13: 0.091152399 | D13: 151 | E13: 0.11861744
A14: 200.0000 - 250.0000 | B14: 69933943 | C14: 0.13640767 | D14: 209 | E14: 0.1641791
A15: 150.0000 - 200.0000 | B15: 224142774 | C15: 0.43719533 | D15: 572 | E15: 0.44933229
A16: 100.0000 - 150.0000 | B16: 148053911 | C16: 0.28878235 | D16: 281 | E16: 0.22073841
A17: 50.0000 - 100.0000 | B17: 10536404 | C17: 0.020551484 | D17: 20 | E17: 0.015710919
A20: RACE.MI Statistics Daily 02-Jan-2019 - 29-Dec-2023
A21: Price | D21: Volume | I21: Up/Down | K21: Price Change (Close-Close) | N21: Turnover
A22: High | B22: 346 | C22: 45272 | D22: Max | E22: 3346662 | F22: 45184 | G22: Advancing | H22: 270883490 | I22: Up | J22: 668 | K22: Up | L22: 0.11020241 | M22: 43496 | N22: Max | O22: 9.5098005e+08 | P22: 45184
A23: Low | B23: 84.3 | C23: 43467 | D23: Min | E23: 103437 | F23: 44928 | G23: Declining | H23: 239253185 | I23: Down | J23: 595 | K23: Down | L23: -0.10259388 | M23: 43902 | N23: Min | O23: 18739691 | P23: 43486
A24: Avg (Close) | B24: 188.92134 | D24: Avg | E24: 402736.35 | G24: Total | H24: 512683371 | I24: Unch | J24: 9 | K24: Period | L24: 2.5275081 | M24: 02-Jan-2019 - 29-Dec-2023 | N24: Avg | O24: 72407594
A25: Avg (High-Low) | B25: 215.15
A28: RACE.MI History Daily 02-Jan-2019 - 29-Dec-2023
A29: Exchange Date | B29: Close | C29: Net | D29: %Chg | E29: Open | F29: Low | G29: High | H29: Volume | I29: Turnover - EUR | J29: O-C | K29: H-L | L29: %CVol | M29: Flow | N29: Trade Price
A30: 43467 | B30: 86.52 | E30: 86.5 | F30: 84.3 | G30: 86.92 | H30: 424022 | I30: 36369146 | J30: 0.02 | K30: 2.62 | M30: 0 | N30: 86.52
A31: 43468 | B31: 85.6 | C31: -0.92 | D31: -0.01063338 | E31: 85.44 | F31: 84.6 | G31: 87.1 | H31: 558777 | I31: 47762846 | J31: 0.16 | K31: 2.5 | L31: 0.31780191 | M31: -47762846 | N31: 85.6
A32: 43469 | B32: 89.4 | C32: 3.8 | D32: 0.044392523 | E32: 86.14 | F32: 86.02 | G32: 89.54 | H32: 689799 | I32: 60870257 | J32: 3.26 | K32: 3.52 | L32: 0.23447994 | M32: 13107411 | N32: 89.4
A33: 43472 | B33: 91.32 | C33: 1.92 | D33: 0.02147651 | E33: 90 | F33: 89.24 | G33: 91.64 | H33: 465015 | I33: 42155654 | J33: 1.32 | K33: 2.4 | L33: -0.32586884 | M33: 55263065 | N33: 91.32
A34: 43473 | B34: 94.14 | C34: 2.82 | D34: 0.03088042 | E34: 91.6 | F34: 91.16 | G34: 95.42 | H34: 720848 | I34: 67506900 | J34: 2.54 | K34: 4.26 | L34: 0.55016075 | M34: 1.2276997e+08 | N34: 94.14
A35: 43474 | B35: 96.7 | C35: 2.56 | D35: 0.027193542 | E35: 95.32 | F35: 95.02 | G35: 98.94 | H35: 841186 | I35: 81771668 | J35: 1.38 | K35: 3.92 | L35: 0.16693949 | M35: 2.0454163e+08 | N35: 96.7
A36: 43475 | B36: 96.36 | C36: -0.34 | D36: -0.003516029 | E36: 95.74 | F36: 94.94 | G36: 96.78 | H36: 371601 | I36: 35633072 | J36: 0.62 | K36: 1.84 | L36: -0.55824158 | M36: 1.6890856e+08 | N36: 96.36
A37: 43476 | B37: 96.76 | C37: 0.4 | D37: 0.0041511 | E37: 97.04 | F37: 96 | G37: 97.48 | H37: 445181 | I37: 43070945 | J37: 0.28 | K37: 1.48 | L37: 0.19800808 | M37: 2.1197951e+08 | N37: 96.76
A38: 43479 | B38: 96.36 | C38: -0.4 | D38: -0.0041339396 | E38: 96 | F38: 95.64 | G38: 97.34 | H38: 356353 | I38: 34379788 | J38: 0.36 | K38: 1.7 | L38: -0.19953233 | M38: 1.7759972e+08 | N38: 96.36
A39: 43480 | B39: 98.28 | C39: 1.92 | D39: 0.01992528 | E39: 98 | F39: 97.86 | G39: 98.74 | H39: 539506 | I39: 53058096 | J39: 0.28 | K39: 0.88 | L39: 0.51396509 | M39: 2.3065781e+08 | N39: 98.28
A40: 43481 | B40: 99.26 | C40: 0.98 | D40: 0.00997151 | E40: 98.68 | F40: 97.54 | G40: 99.32 | H40: 501642 | I40: 49519330 | J40: 0.58 | K40: 1.78 | L40: -0.070182723 | M40: 2.8017714e+08 | N40: 99.26
A41: 43482 | B41: 99.52 | C41: 0.26 | D41: 0.0026193834 | E41: 99.28 | F41: 98.7 | G41: 100.15 | H41: 458580 | I41: 45659388 | J41: 0.24 | K41: 1.45 | L41: -0.085842095 | M41: 3.2583653e+08 | N41: 99.52
A42: 43483 | B42: 99.5 | C42: -0.02 | D42: -0.00020096463 | E42: 100.15 | F42: 99.06 | G42: 100.55 | H42: 550424 | I42: 54882475 | J42: 0.65 | K42: 1.49 | L42: 0.20027912 | M42: 2.7095406e+08 | N42: 99.5
... A1302: 45289 | B1302: 305.2 | C1302: 0.8 | D1302: 0.0026281209 | E1302: 306 | F1302: 305.2 | G1302: 308.2 | H1302: 172419 | I1302: 52815977 | J1302: 0.8 | K1302: 3 | L1302: 0.22907103 | M1302: 5.6501469e+09 | N1302: 305.2

Sheet LVMH.PA
A1: LVMH Moet Hennessy Louis Vuitton SE | Price History 13-Feb-2026 09:47
A4: LVMH.PA
A5: Interval: Daily
A6: History Period: 01-Jan-2019 - 31-Dec-2023
A7: Currency Conversion: EUR
A10: VAP: Total | B10: 618839526
A11: Price | B11: Volume | C11: %Volume | D11: Count | E11: %Count
A12: 900.0000 - 1,000.0000 | B12: 729018 | C12: 0.0011780405 | D12: 2 | E12: 0.0015600624
A13: 800.0000 - 900.0000 | B13: 44247839 | C13: 0.071501314 | D13: 133 | E13: 0.10374415
A14: 700.0000 - 800.0000 | B14: 64840622 | C14: 0.10477776 | D14: 168 | E14: 0.13104524
A15: 600.0000 - 700.0000 | B15: 141063483 | C15: 0.22794841 | D15: 350 | E15: 0.27301092
A16: 500.0000 - 600.0000 | B16: 53435799 | C16: 0.086348394 | D16: 123 | E16: 0.095943838
A17: 400.0000 - 500.0000 | B17: 77019555 | C17: 0.12445804 | D17: 155 | E17: 0.12090484
A18: 300.0000 - 400.0000 | B18: 205354043 | C18: 0.33183731 | D18: 310 | E18: 0.24180967
A19: 200.0000 - 300.0000 | B19: 32149167 | C19: 0.051950733 | D19: 41 | E19: 0.031981279
A22: LVMH.PA Statistics Daily 02-Jan-2019 - 29-Dec-2023
A23: Price | D23: Volume | I23: Up/Down | K23: Price Change (Close-Close) | N23: Turnover
A24: High | B24: 904.6 | C24: 45040 | D24: Max | E24: 3098476 | F24: 43902 | G24: Advancing | H24: 326195374 | I24: Up | J24: 684 | K24: Up | L24: 0.095437193 | M24: 44629 | N24: Max | O24: 1.238865e+09 | P24: 44895
A25: Low | B25: 243.65 | C25: 43468 | D25: Min | E25: 48392 | F25: 44554 | G25: Declining | H25: 289714686 | I25: Down | J25: 589 | K25: Down | L25: -0.086778737 | M25: 43902 | N25: Min | O25: 27136508 | P25: 43823
A26: Avg (Close) | B26: 563.14785 | D26: Avg | E26: 482714.14 | G26: Total | H26: 618839526 | I26: Unch | J26: 8 | K26: Period | L26: 1.8961705 | M26: 02-Jan-2019 - 29-Dec-2023 | N26: Avg | O26: 2.5108812e+08
A27: Avg (High-Low) | B27: 574.125
A30: LVMH.PA History Daily 02-Jan-2019 - 29-Dec-2023
A31: Exchange Date | B31: Close | C31: Net | D31: %Chg | E31: Open | F31: Low | G31: High | H31: Volume | I31: Turnover - EUR | J31: O-C | K31: H-L | L31: %CVol | M31: Flow | N31: Trade Price
A32: 43467 | B32: 253.3 | E32: 254.05 | F32: 249.8 | G32: 256.05 | H32: 561858 | I32: 142382105 | J32: 0.75 | K32: 6.25 | M32: 0 | N32: 253.3
A33: 43468 | B33: 243.65 | C33: -9.65 | D33: -0.038097118 | E33: 248 | F33: 243.65 | G33: 248.85 | H33: 785119 | I33: 192560231 | J33: 4.35 | K33: 5.2 | L33: 0.39736197 | M33: -192560231 | N33: 243.65
A34: 43469 | B34: 251.15 | C34: 7.5 | D34: 0.030781859 | E34: 246.45 | F34: 244.1 | G34: 251.95 | H34: 886586 | I34: 220071534 | J34: 4.7 | K34: 7.85 | L34: 0.12923773 | M34: 27511303 | N34: 251.15
A35: 43472 | B35: 250.7 | C35: -0.45 | D35: -0.0017917579 | E35: 252.65 | F35: 249.3 | G35: 253.5 | H35: 550835 | I35: 138309522 | J35: 1.95 | K35: 4.2 | L35: -0.37870099 | M35: -110798219 | N35: 250.7
A36: 43473 | B36: 258.55 | C36: 7.85 | D36: 0.031312325 | E36: 251.5 | F36: 250.1 | G36: 262.5 | H36: 742574 | I36: 191770345 | J36: 7.05 | K36: 12.4 | L36: 0.3480879 | M36: 80972126 | N36: 258.55
A37: 43474 | B37: 261.55 | C37: 3 | D37: 0.011603172 | E37: 261.75 | F37: 261.35 | G37: 266.2 | H37: 646844 | I37: 170254062 | J37: 0.2 | K37: 4.85 | L37: -0.12891644 | M37: 251226188 | N37: 261.55
A38: 43475 | B38: 259.15 | C38: -2.4 | D38: -0.0091760658 | E38: 259.5 | F38: 257.65 | G38: 261.1 | H38: 666326 | I38: 172683918 | J38: 0.35 | K38: 3.45 | L38: 0.030118545 | M38: 78542270 | N38: 259.15
A39: 43476 | B39: 258.3 | C39: -0.85 | D39: -0.0032799537 | E39: 261 | F39: 256.7 | G39: 262.2 | H39: 525969 | I39: 136157192 | J39: 2.7 | K39: 5.5 | L39: -0.21064314 | M39: -57614922 | N39: 258.3
A40: 43479 | B40: 251.7 | C40: -6.6 | D40: -0.025551684 | E40: 254.55 | F40: 249.1 | G40: 254.55 | H40: 678686 | I40: 170675623 | J40: 2.85 | K40: 5.45 | L40: 0.29035361 | M40: -228290545 | N40: 251.7
A41: 43480 | B41: 250.8 | C41: -0.9 | D41: -0.0035756853 | E41: 253.95 | F41: 249.7 | G41: 254.7 | H41: 600204 | I41: 150921379 | J41: 3.15 | K41: 5 | L41: -0.11563816 | M41: -379211924 | N41: 250.8
A42: 43481 | B42: 248.95 | C42: -1.85 | D42: -0.0073763955 | E42: 252 | F42: 248.65 | G42: 252.7 | H42: 615045 | I42: 153805571 | J42: 3.05 | K42: 4.05 | L42: 0.024726593 | M42: -533017495 | N42: 248.95
A43: 43482 | B43: 246.55 | C43: -2.4 | D43: -0.0096404901 | E43: 248 | F43: 245.5 | G43: 248.7 | H43: 784017 | I43: 193418639 | J43: 1.45 | K43: 3.2 | L43: 0.27473112 | M43: -726436134 | N43: 246.55
A44: 43483 | B44: 253.4 | C44: 6.85 | D44: 0.027783411 | E44: 247.7 | F44: 247.1 | G44: 254.5 | H44: 1129978 | I44: 284396691 | J44: 5.7 | K44: 7.4 | L44: 0.44126722 | M44: -442039443 | N44: 253.4
... A1313: 45289 | B1313: 733.6 | C1313: 2.6 | D1313: 0.0035567715 | E1313: 733 | F1313: 732.2 | G1313: 738.3 | H1313: 139158 | I1313: 1.0226652e+08 | J1313: 0.6 | K1313: 6.1 | L1313: -0.14323183 | M1313: 1.6637251e+10 | N1313: 733.6

Sheet PAH3.DE
A1: Porsche Automobil Holding SE | Price History 13-Feb-2026 09:52
A4: PSHG_p.DE
A5: Interval: Daily
A6: History Period: 01-Jan-2019 - 31-Dec-2023
A7: Currency Conversion: EUR
A10: VAP: Total | B10: 842833106
A11: Price | B11: Volume | C11: %Volume | D11: Count | E11: %Count
A12: 100.0000 - 110.0000 | B12: 736860 | C12: 0.00087426561 | D12: 1 | E12: 0.00078616352
A13: 90.0000 - 100.0000 | B13: 51771024 | C13: 0.061425001 | D13: 82 | E13: 0.064465409
A14: 80.0000 - 90.0000 | B14: 119951701 | C14: 0.14231964 | D14: 178 | E14: 0.13993711
A15: 70.0000 - 80.0000 | B15: 64555407 | C15: 0.076593345 | D15: 84 | E15: 0.066037736
A16: 60.0000 - 70.0000 | B16: 131124230 | C16: 0.15557556 | D16: 215 | E16: 0.16902516
A17: 50.0000 - 60.0000 | B17: 331375895 | C17: 0.39316905 | D17: 531 | E17: 0.41745283
A18: 40.0000 - 50.0000 | B18: 125188609 | C18: 0.14853309 | D18: 166 | E18: 0.13050314
A19: 30.0000 - 40.0000 | B19: 18129380 | C19: 0.021510047 | D19: 15 | E19: 0.011792453
A22: PSHG_p.DE Statistics Daily 02-Jan-2019 - 29-Dec-2023
A23: Price | D23: Volume | I23: Up/Down | K23: Price Change (Close-Close) | N23: Turnover
A24: High | B24: 102 | C24: 44354 | D24: Max | E24: 6168811 | F24: 44820 | G24: Advancing | H24: 399931761 | I24: Up | J24: 612 | K24: Up | L24: 0.16605052 | M24: 43914 | N24: Max | O24: 4.1225529e+08 | P24: 44820
A25: Low | B25: 28.28 | C25: 43909 | D25: Min | E25: 151260 | F25: 43826 | G25: Declining | H25: 437564272 | I25: Down | J25: 649 | K25: Down | L25: -0.17137592 | M25: 43902 | N25: Min | O25: 10168327 | P25: 43826
A26: Avg (Close) | B26: 63.598868 | D26: Avg | E26: 662604.64 | G26: Total | H26: 842833106 | I26: Unch | J26: 10 | K26: Period | L26: -0.091408395 | M26: 02-Jan-2019 - 29-Dec-2023 | N26: Avg | O26: 41836848
A27: Avg (High-Low) | B27: 65.14
A30: PSHG_p.DE History Daily 02-Jan-2019 - 29-Dec-2023
A31: Exchange Date | B31: Close | C31: Net | D31: %Chg | E31: Open | F31: Low | G31: High | H31: Volume | I31: Turnover - EUR | J31: O-C | K31: H-L | L31: %CVol | M31: Flow | N31: Trade Price
A32: 43467 | B32: 50.98 | E32: 51.7 | F32: 50.14 | G32: 51.74 | H32: 658583 | I32: 33396470 | J32: 0.72 | K32: 1.6 | M32: 0 | N32: 50.98
A33: 43468 | B33: 50.28 | C33: -0.7 | D33: -0.013730875 | E33: 50.26 | F33: 49.89 | G33: 50.94 | H33: 397618 | I33: 20017680 | J33: 0.02 | K33: 1.05 | L33: -0.39625226 | M33: -20017680 | N33: 50.28
A34: 43469 | B34: 52.78 | C34: 2.5 | D34: 0.049721559 | E34: 50.8 | F34: 50.52 | G34: 52.8 | H34: 588757 | I34: 30702840 | J34: 1.98 | K34: 2.28 | L34: 0.48071013 | M34: 10685160 | N34: 52.78
A35: 43472 | B35: 53.16 | C35: 0.38 | D35: 0.0071996969 | E35: 53.04 | F35: 52.62 | G35: 53.6 | H35: 366768 | I35: 19489790 | J35: 0.12 | K35: 0.98 | L35: -0.3770469 | M35: 30174950 | N35: 53.16
A36: 43473 | B36: 54.1 | C36: 0.94 | D36: 0.017682468 | E36: 53.16 | F36: 52.38 | G36: 55.18 | H36: 623204 | I36: 33589550 | J36: 0.94 | K36: 2.8 | L36: 0.69917768 | M36: 63764500 | N36: 54.1
A37: 43474 | B37: 55.6 | C37: 1.5 | D37: 0.027726433 | E37: 54.8 | F37: 54.8 | G37: 56.48 | H37: 561648 | I37: 31327680 | J37: 0.8 | K37: 1.68 | L37: -0.098773435 | M37: 95092180 | N37: 55.6
A38: 43475 | B38: 55.6 | C38: 0 | D38: 0 | E38: 55 | F38: 54.56 | G38: 56.02 | H38: 373678 | I38: 20722070 | J38: 0.6 | K38: 1.46 | L38: -0.33467581 | M38: 115814250 | N38: 55.6
A39: 43476 | B39: 55.1 | C39: -0.5 | D39: -0.0089928058 | E39: 55.9 | F39: 54.44 | G39: 56 | H39: 432453 | I39: 23792790 | J39: 0.8 | K39: 1.56 | L39: 0.15728783 | M39: 92021460 | N39: 55.1
A40: 43479 | B40: 54.96 | C40: -0.14 | D40: -0.0025408348 | E40: 54.52 | F40: 54.5 | G40: 55.72 | H40: 534725 | I40: 29485110 | J40: 0.44 | K40: 1.22 | L40: 0.23649275 | M40: 62536350 | N40: 54.96
A41: 43480 | B41: 55.5 | C41: 0.54 | D41: 0.0098253275 | E41: 55.52 | F41: 55.1 | G41: 56.36 | H41: 462254 | I41: 25680600 | J41: 0.02 | K41: 1.26 | L41: -0.13552948 | M41: 88216950 | N41: 55.5
A42: 43481 | B42: 55.94 | C42: 0.44 | D42: 0.0079279279 | E42: 55.78 | F42: 55.14 | G42: 55.94 | H42: 322382 | I42: 17967640 | J42: 0.16 | K42: 0.8 | L42: -0.30258689 | M42: 106184590 | N42: 55.94
A43: 43482 | B43: 55.24 | C43: -0.7 | D43: -0.012513407 | E43: 55.48 | F43: 54.64 | G43: 55.8 | H43: 333683 | I43: 18435920 | J43: 0.24 | K43: 1.16 | L43: 0.035054687 | M43: 87748670 | N43: 55.24
A44: 43483 | B44: 56.02 | C44: 0.78 | D44: 0.014120203 | E44: 55.8 | F44: 55.56 | G44: 56.56 | H44: 522415 | I44: 29308180 | J44: 0.22 | K44: 1 | L44: 0.56560268 | M44: 117056850 | N44: 56.02
... A1303: 45289 | B1303: 46.32 | C1303: -0.09 | D1303: -0.0019392372 | E1303: 46.4 | F1303: 46.18 | G1303: 46.58 | H1303: 317240 | I1303: 14702836 | J1303: 0.08 | K1303: 0.4 | L1303: -0.22161154 | M1303: -2.0094871e+09 | N1303: 46.32

Sheet HRMS.PA
A1: Hermes International SCA | Price History 20-Feb-2026 14:29
E2: =CERCA.VERT('HRMS.PA'!A33;'HRMS.PA'!B33
A4: HRMS.PA
A5: Interval: Daily
A6: History Period: 01-Jan-2019 - 31-Dec-2023
A7: Currency Conversion: EUR
A10: VAP: Total | B10: 80060537
A11: Price | B11: Volume | C11: %Volume | D11: Count | E11: %Count
A12: 2,000.0000 - 2,200.0000 | B12: 757629 | C12: 0.0094632016 | D12: 11 | E12: 0.0085803432
A13: 1,800.0000 - 2,000.0000 | B13: 8175055 | C13: 0.10211092 | D13: 154 | E13: 0.1201248
A14: 1,600.0000 - 1,800.0000 | B14: 6695819 | C14: 0.08363445 | D14: 98 | E14: 0.076443058
A15: 1,400.0000 - 1,600.0000 | B15: 5870654 | C15: 0.073327687 | D15: 77 | E15: 0.060062402
A16: 1,200.0000 - 1,400.0000 | B16: 14923571 | C16: 0.18640358 | D16: 231 | E16: 0.18018721
A17: 1,000.0000 - 1,200.0000 | B17: 8719754 | C17: 0.10891451 | D17: 124 | E17: 0.096723869
A18: 800.0000 - 1,000.0000 | B18: 6941506 | C18: 0.086703216 | D18: 125 | E18: 0.0975039
A19: 600.0000 - 800.0000 | B19: 22188520 | C19: 0.27714678 | D19: 375 | E19: 0.2925117
A20: 400.0000 - 600.0000 | B20: 5788029 | C20: 0.072295655 | D20: 87 | E20: 0.067862715
A23: HRMS.PA Statistics Daily 02-Jan-2019 - 29-Dec-2023
A24: Price | D24: Volume | I24: Up/Down | K24: Price Change (Close-Close) | N24: Turnover
A25: High | B25: 2063.5 | C25: 45274 | D25: Max | E25: 892837 | F25: 44547 | G25: Advancing | H25: 42540746 | I25: Up | J25: 713 | K25: Up | L25: 0.083294771 | M25: 44629 | N25: Max | O25: 1369706514 | P25: 44547
A26: Low | B26: 462.4 | C26: 43468 | D26: Min | E26: 8388 | F26: 44189 | G26: Declining | H26: 36717675 | I26: Down | J26: 553 | K26: Down | L26: -0.065414091 | M26: 45069 | N26: Min | O26: 7144065.4 | P26: 44189
A27: Avg (Close) | B27: 1127.4669 | D27: Avg | E27: 62449.717 | G27: Total | H27: 80060537 | I27: Unch | J27: 15 | K27: Period | L27: 3.0175879 | M27: 02-Jan-2019 - 29-Dec-2023 | N27: Avg | O27: 70556955
A28: Avg (High-Low) | B28: 1262.95
A31: HRMS.PA History Daily 02-Jan-2019 - 29-Dec-2023
A32: Exchange Date | B32: Close | C32: Net | D32: %Chg | E32: Open | F32: Low | G32: High | H32: Volume | I32: Turnover - EUR | J32: O-C | K32: H-L | L32: %CVol | M32: Flow | N32: Trade Price
A33: 43467 | B33: 477.6 | E33: 480 | F33: 471.7 | G33: 480.3 | H33: 63153 | I33: 30130577 | J33: 2.4 | K33: 8.6 | M33: 0 | N33: 477.6
A34: 43468 | B34: 464 | C34: -13.6 | D34: -0.028475712 | E34: 472 | F34: 462.4 | G34: 475.4 | H34: 62051 | I34: 28869580 | J34: 8 | K34: 13 | L34: -0.017449686 | M34: -28869580 | N34: 464
A35: 43469 | B35: 477.8 | C35: 13.8 | D35: 0.029741379 | E35: 467.8 | F35: 466.2 | G35: 477.8 | H35: 60823 | I35: 28768701 | J35: 10 | K35: 11.6 | L35: -0.019790173 | M35: -100879 | N35: 477.8
A36: 43472 | B36: 472.2 | C36: -5.6 | D36: -0.011720385 | E36: 480.3 | F36: 470.6 | G36: 481.3 | H36: 49203 | I36: 23307069 | J36: 8.1 | K36: 10.7 | L36: -0.19104615 | M36: -23407948 | N36: 472.2
A37: 43473 | B37: 479.9 | C37: 7.7 | D37: 0.01630665 | E37: 474.4 | F37: 468 | G37: 485.2 | H37: 87020 | I37: 41651283 | J37: 5.5 | K37: 17.2 | L37: 0.76859135 | M37: 18243335 | N37: 479.9
A38: 43474 | B38: 491.2 | C38: 11.3 | D38: 0.023546572 | E38: 484.5 | F38: 484.5 | G38: 498 | H38: 87659 | I38: 43265785 | J38: 6.7 | K38: 13.5 | L38: 0.0073431395 | M38: 61509120 | N38: 491.2
A39: 43475 | B39: 489.9 | C39: -1.3 | D39: -0.0026465798 | E39: 489 | F39: 484.1 | G39: 490.6 | H39: 66099 | I39: 32298833 | J39: 0.9 | K39: 6.5 | L39: -0.24595307 | M39: 29210287 | N39: 489.9
A40: 43476 | B40: 496.4 | C40: 6.5 | D40: 0.013268014 | E40: 499.2 | F40: 493.2 | G40: 501 | H40: 67953 | I40: 33769831 | J40: 2.8 | K40: 7.8 | L40: 0.028048836 | M40: 62980118 | N40: 496.4
A41: 43479 | B41: 488.7 | C41: -7.7 | D41: -0.015511684 | E41: 491 | F41: 485.6 | G41: 491.5 | H41: 53667 | I41: 26200589 | J41: 2.3 | K41: 5.9 | L41: -0.21023354 | M41: 36779529 | N41: 488.7
A42: 43480 | B42: 494 | C42: 5.3 | D42: 0.010845099 | E42: 491 | F42: 490.1 | G42: 495.2 | H42: 57317 | I42: 28258481 | J42: 3 | K42: 5.1 | L42: 0.068012 | M42: 65038010 | N42: 494
A43: 43481 | B43: 488.9 | C43: -5.1 | D43: -0.010323887 | E43: 495 | F43: 487.6 | G43: 496.4 | H43: 51390 | I43: 25185690 | J43: 6.1 | K43: 8.8 | L43: -0.10340737 | M43: 39852320 | N43: 488.9
A44: 43482 | B44: 495.7 | C44: 6.8 | D44: 0.013908775 | E44: 487.7 | F44: 486.5 | G44: 495.7 | H44: 70663 | I44: 34891856 | J44: 8 | K44: 9.2 | L44: 0.37503405 | M44: 74744176 | N44: 495.7
A45: 43483 | B45: 500.4 | C45: 4.7 | D45: 0.0094815413 | E45: 497.1 | F45: 495.4 | G45: 500.4 | H45: 56376 | I45: 28127423 | J45: 3.3 | K45: 5 | L45: -0.20218502 | M45: 102871599 | N45: 500.4
... A1314: 45289 | B1314: 1918.8 | C1314: 8 | D1314: 0.0041867281 | E1314: 1921.8 | F1314: 1914 | G1314: 1932 | H1314: 24471 | I1314: 47011562 | J1314: 3 | K1314: 18 | L1314: -0.30659375 | M1314: 6.9826148e+09 | N1314: 1918.8

Sheet .STOXX
A1: STOXX Europe 600 EUR Price Index | Price History 20-Feb-2026 14:32
A4: .STOXX
A5: Interval: Daily
A6: History Period: 01-Jan-2019 - 31-Dec-2023
A7: Currency Conversion: EUR
A10: VAP: Total | B10: 2639882816820
A11: Price | B11: Volume | C11: %Volume | D11: Count | E11: %Count
A12: 450.00 - 500.00 | B12: 782927998200 | C12: 0.2965768 | D12: 419 | E12: 0.32632399
A13: 400.00 - 450.00 | B13: 825249432860 | C13: 0.31260836 | D13: 411 | E13: 0.32009346
A14: 350.00 - 400.00 | B14: 818472082110 | C14: 0.31004107 | D14: 385 | E14: 0.29984424
A15: 300.00 - 350.00 | B15: 172387364830 | C15: 0.065301143 | D15: 62 | E15: 0.048286604
A16: 250.00 - 300.00 | B16: 40845938820 | C16: 0.015472633 | D16: 7 | E16: 0.0054517134
A19: .STOXX Statistics Daily 02-Jan-2019 - 29-Dec-2023
A20: Price | D20: Volume | I20: Up/Down | K20: Price Change (Close-Close) | N20: Turnover
A21: High | B21: 495.46 | C21: 44565 | D21: Max | E21: 6941570510 | F21: 43902 | G21: Advancing | H21: 1436347251140 | I21: Up | J21: 711 | K21: Up | L21: 0.084049495 | M21: 43914 | N21: Max | O21: 94270239770000 | P21: 44293
A22: Low | B22: 268.57 | C22: 43906 | D22: Min | E22: 424941260 | F22: 44438 | G22: Declining | H22: 1197424809580 | I22: Down | J22: 571 | K22: Down | L22: -0.11477624 | M22: 43902 | N22: Min | O22: 7508190000 | P22: 44922
A23: Avg (Close) | B23: 418.64953 | D23: Avg | E23: 2.0503541e+09 | G23: Total | H23: 2642906377280 | I23: Unch | J23: 2 | K23: Period | L23: 0.42045016 | M23: 02-Jan-2019 - 29-Dec-2023 | N23: Avg | O23: 5.3855611e+11
A24: Avg (High-Low) | B24: 382.015
A27: .STOXX History Daily 02-Jan-2019 - 29-Dec-2023
A28: Exchange Date | B28: Close | C28: Net | D28: %Chg | E28: Open | F28: Low | G28: High | H28: Volume | I28: Turnover - EUR | J28: O-C | K28: H-L | L28: %CVol | M28: Flow | N28: Trade Price
A29: 43467 | B29: 337.21 | E29: 335.86 | F29: 331.8 | G29: 337.83 | H29: 1633455400 | I29: 393026880000 | J29: 1.35 | K29: 6.03 | M29: 0 | N29: 337.21
A30: 43468 | B30: 333.92 | C30: -3.29 | D30: -0.0097565315 | E30: 335.64 | F30: 333.51 | G30: 336.78 | H30: 1849855190 | I30: 443881760000 | J30: 1.72 | K30: 3.27 | L30: 0.13247977 | M30: -443881760000 | N30: 333.92
A31: 43469 | B31: 343.38 | C31: 9.46 | D31: 0.028330139 | E31: 335.47 | F31: 335.47 | G31: 343.9 | H31: 1937042900 | I31: 461719280000 | J31: 7.91 | K31: 8.43 | L31: 0.047132181 | M31: 17837520000 | N31: 343.38
A32: 43472 | B32: 342.88 | C32: -0.5 | D32: -0.0014561128 | E32: 344.03 | F32: 341.38 | G32: 344.75 | H32: 1804117070 | I32: 447216080000 | J32: 1.15 | K32: 3.37 | L32: -0.06862307 | M32: -429378560000 | N32: 342.88
A33: 43473 | B33: 345.85 | C33: 2.97 | D33: 0.0086619225 | E33: 342.99 | F33: 342.99 | G33: 348.06 | H33: 1913749670 | I33: 445914720000 | J33: 2.86 | K33: 5.07 | L33: 0.060768008 | M33: 16536160000 | N33: 345.85
A34: 43474 | B34: 347.7 | C34: 1.85 | D34: 0.0053491398 | E34: 346.87 | F34: 346.79 | G34: 349.81 | H34: 2144138280 | I34: 527039040000 | J34: 0.83 | K34: 3.02 | L34: 0.12038597 | M34: 543575200000 | N34: 347.7
A35: 43475 | B35: 348.88 | C35: 1.18 | D35: 0.0033937302 | E35: 347.07 | F35: 344.84 | G35: 348.92 | H35: 1735309250 | I35: 404558040000 | J35: 1.81 | K35: 4.08 | L35: -0.19067288 | M35: 948133240000 | N35: 348.88
A36: 43476 | B36: 349.2 | C36: 0.32 | D36: 0.00091722082 | E36: 349.03 | F36: 347.74 | G36: 350.18 | H36: 1798572630 | I36: 464683920000 | J36: 0.17 | K36: 2.44 | L36: 0.036456545 | M36: 1412817160000 | N36: 349.2
A37: 43479 | B37: 347.51 | C37: -1.69 | D37: -0.0048396334 | E37: 348.27 | F37: 345.86 | G37: 348.27 | H37: 1682199480 | I37: 405931520000 | J37: 0.76 | K37: 2.41 | L37: -0.064703058 | M37: 1006885640000 | N37: 347.51
A38: 43480 | B38: 348.71 | C38: 1.2 | D38: 0.003453138 | E38: 348.26 | F38: 347.11 | G38: 350.6 | H38: 1892783030 | I38: 432152960000 | J38: 0.45 | K38: 3.49 | L38: 0.12518346 | M38: 1439038600000 | N38: 348.71
A39: 43481 | B39: 350.59 | C39: 1.88 | D39: 0.0053912994 | E39: 349.92 | F39: 348.82 | G39: 350.93 | H39: 2062955570 | I39: 481969440000 | J39: 0.67 | K39: 2.11 | L39: 0.089905994 | M39: 1921008040000 | N39: 350.59
A40: 43482 | B40: 350.73 | C40: 0.14 | D40: 0.00039932685 | E40: 349.71 | F40: 348.29 | G40: 351.07 | H40: 1675595790 | I40: 400220920000 | J40: 1.02 | K40: 2.78 | L40: -0.18776933 | M40: 2321228960000 | N40: 350.73
A41: 43483 | B41: 357.05 | C41: 6.32 | D41: 0.018019559 | E41: 351.98 | F41: 351.98 | G41: 357.29 | H41: 2606230090 | I41: 525182800000 | J41: 5.07 | K41: 5.31 | L41: 0.55540501 | M41: 2846411760000 | N41: 357.05
... A341: 43910 | B341: 293.04 | C341: 5.24 | D341: 0.018207088 | E341: 291.01 | F341: 291.01 | G341: 301.97 | H341: 6722736580 | I341: 1055730720000 | J341: 2.03 | K341: 10.96 | L341: 0.32126078 | M341: 20095949540000 | N341: 293.04
A342: 43913 | B342: 280.43 | C342: -12.61 | D342: -0.043031668 | E342: 288.31 | F342: 278.41 | G342: 292.04 | J342: 7.88 | K342: 13.63 | M342: 20095949540000 | N342: 280.43
A343: 43914 | B343: 304 | C343: 23.57 | D343: 0.084049495 | E343: 284.01 | F343: 284.01 | G343: 304 | H343: 4203018550 | I343: 685002880000 | J343: 19.99 | K343: 19.99 | L343: -0.37480541 | M343: 20780952420000 | N343: 304
A344: 43915 | B344: 313.38 | C344: 9.38 | D344: 0.030855263 | E344: 307.86 | F344: 301.85 | G344: 318.52 | H344: 4522038960 | I344: 784676880000 | J344: 5.52 | K344: 16.67 | L344: 0.075902689 | M344: 21565629300000 | N344: 313.38
A345: 43916 | B345: 321.38 | C345: 8 | D345: 0.025528113 | E345: 310.02 | F345: 306.04 | G345: 321.38 | H345: 3736732880 | I345: 705252720000 | J345: 11.36 | K345: 15.34 | L345: -0.17366194 | M345: 22270882020000 | N345: 321.38
A346: 43917 | B346: 310.9 | C346: -10.48 | D346: -0.032609372 | E346: 319.17 | F346: 306.7 | G346: 319.17 | H346: 3422201650 | I346: 681287360000 | J346: 8.27 | K346: 12.47 | L346: -0.084172789 | M346: 21589594660000 | N346: 310.9
A347: 43920 | B347: 314.88 | C347: 3.98 | D347: 0.012801544 | E347: 311.4 | F347: 303.38 | G347: 314.88 | H347: 2940248480 | I347: 509752400000 | J347: 3.48 | K347: 11.5 | L347: -0.14083132 | M347: 22099347060000 | N347: 314.88
...

Sheet Andamento quotazioni RACE.MI
M1: CAGR | N1: =_xlfn.RRI(5,'Confronto prezzi'!B2,'Confronto prezzi'!B1274) -> 0.2867483

Sheet Confronto prezzi
A1: Exchange Date | B1: RACE.MI | C1: LVMH.PA | D1: PAH3.DE | E1: HRMS.PA | F1: .STOXX
A2: 43467 | B2: 86.52 | C2: =VLOOKUP(A2, LVMH.PA!$A$32:$B$2000, 2, FALSE) -> 253.3 | D2: =VLOOKUP(A2, 'PAH3.DE'!$A$31:$B$1500, 2, FALSE) -> 50.98 | E2: =VLOOKUP(A2,HRMS.PA!$A$33:$B$2000,2,FALSE) -> 477.6 | F2: =VLOOKUP(A2,'.STOXX'!$A$27:$B$1500,2,FALSE) -> 337.21 | I2: CAGR (.STOXX) 5y | J2: =_xlfn.RRI(5,F2,F1274) -> 0.072717092
A3: 43468 | B3: 85.6 | C3: =VLOOKUP(A3, LVMH.PA!$A$32:$B$2000, 2, FALSE) -> 243.65 | D3: =VLOOKUP(A3, 'PAH3.DE'!$A$31:$B$1500, 2, FALSE) -> 50.28 | E3: =VLOOKUP(A3,HRMS.PA!$A$33:$B$2000,2,FALSE) -> 464 | F3: =VLOOKUP(A3,'.STOXX'!$A$27:$B$1500,2,FALSE) -> 333.92 | I3: Performance 5y | J3: =F1274/F2-1 -> 0.42045016
A4: 43469 | B4: 89.4 | C4: =VLOOKUP(A4, LVMH.PA!$A$32:$B$2000, 2, FALSE) -> 251.15 | D4: =VLOOKUP(A4, 'PAH3.DE'!$A$31:$B$1500, 2, FALSE) -> 52.78 | E4: =VLOOKUP(A4,HRMS.PA!$A$33:$B$2000,2,FALSE) -> 477.8 | F4: =VLOOKUP(A4,'.STOXX'!$A$27:$B$1500,2,FALSE) -> 343.38
A5: 43472 | B5: 91.32 | C5: =VLOOKUP(A5, LVMH.PA!$A$32:$B$2000, 2, FALSE) -> 250.7 | D5: =VLOOKUP(A5, 'PAH3.DE'!$A$31:$B$1500, 2, FALSE) -> 53.16 | E5: =VLOOKUP(A5,HRMS.PA!$A$33:$B$2000,2,FALSE) -> 472.2 | F5: =VLOOKUP(A5,'.STOXX'!$A$27:$B$1500,2,FALSE) -> 342.88
A6: 43473 | B6: 94.14 | C6: =VLOOKUP(A6, LVMH.PA!$A$32:$B$2000, 2, FALSE) -> 258.55 | D6: =VLOOKUP(A6, 'PAH3.DE'!$A$31:$B$1500, 2, FALSE) -> 54.1 | E6: =VLOOKUP(A6,HRMS.PA!$A$33:$B$2000,2,FALSE) -> 479.9 | F6: =VLOOKUP(A6,'.STOXX'!$A$27:$B$1500,2,FALSE) -> 345.85
A7: 43474 | B7: 96.7 | C7: =VLOOKUP(A7, LVMH.PA!$A$32:$B$2000, 2, FALSE) -> 261.55 | D7: =VLOOKUP(A7, 'PAH3.DE'!$A$31:$B$1500, 2, FALSE) -> 55.6 | E7: =VLOOKUP(A7,HRMS.PA!$A$33:$B$2000,2,FALSE) -> 491.2 | F7: =VLOOKUP(A7,'.STOXX'!$A$27:$B$1500,2,FALSE) -> 347.7
A8: 43475 | B8: 96.36 | C8: =VLOOKUP(A8, LVMH.PA!$A$32:$B$2000, 2, FALSE) -> 259.15 | D8: =VLOOKUP(A8, 'PAH3.DE'!$A$31:$B$1500, 2, FALSE) -> 55.6 | E8: =VLOOKUP(A8,HRMS.PA!$A$33:$B$2000,2,FALSE) -> 489.9 | F8: =VLOOKUP(A8,'.STOXX'!$A$27:$B$1500,2,FALSE) -> 348.88
A9: 43476 | B9: 96.76 | C9: =VLOOKUP(A9, LVMH.PA!$A$32:$B$2000, 2, FALSE) -> 258.3 | D9: =VLOOKUP(A9, 'PAH3.DE'!$A$31:$B$1500, 2, FALSE) -> 55.1 | E9: =VLOOKUP(A9,HRMS.PA!$A$33:$B$2000,2,FALSE) -> 496.4 | F9: =VLOOKUP(A9,'.STOXX'!$A$27:$B$1500,2,FALSE) -> 349.2
A10: 43479 | B10: 96.36 | C10: =VLOOKUP(A10, LVMH.PA!$A$32:$B$2000, 2, FALSE) -> 251.7 | D10: =VLOOKUP(A10, 'PAH3.DE'!$A$31:$B$1500, 2, FALSE) -> 54.96 | E10: =VLOOKUP(A10,HRMS.PA!$A$33:$B$2000,2,FALSE) -> 488.7 | F10: =VLOOKUP(A10,'.STOXX'!$A$27:$B$1500,2,FALSE) -> 347.51
A11: 43480 | B11: 98.28 | C11: =VLOOKUP(A11, LVMH.PA!$A$32:$B$2000, 2, FALSE) -> 250.8 | D11: =VLOOKUP(A11, 'PAH3.DE'!$A$31:$B$1500, 2, FALSE) -> 55.5 | E11: =VLOOKUP(A11,HRMS.PA!$A$33:$B$2000,2,FALSE) -> 494 | F11: =VLOOKUP(A11,'.STOXX'!$A$27:$B$1500,2,FALSE) -> 348.71
A12: 43481 | B12: 99.26 | C12: =VLOOKUP(A12, LVMH.PA!$A$32:$B$2000, 2, FALSE) -> 248.95 | D12: =VLOOKUP(A12, 'PAH3.DE'!$A$31:$B$1500, 2, FALSE) -> 55.94 | E12: =VLOOKUP(A12,HRMS.PA!$A$33:$B$2000,2,FALSE) -> 488.9 | F12: =VLOOKUP(A12,'.STOXX'!$A$27:$B$1500,2,FALSE) -> 350.59
A13: 43482 | B13: 99.52 | C13: =VLOOKUP(A13, LVMH.PA!$A$32:$B$2000, 2, FALSE) -> 246.55 | D13: =VLOOKUP(A13, 'PAH3.DE'!$A$31:$B$1500, 2, FALSE) -> 55.24 | E13: =VLOOKUP(A13,HRMS.PA!$A$33:$B$2000,2,FALSE) -> 495.7 | F13: =VLOOKUP(A13,'.STOXX'!$A$27:$B$1500,2,FALSE) -> 350.73
A14: 43483 | B14: 99.5 | C14: =VLOOKUP(A14, LVMH.PA!$A$32:$B$2000, 2, FALSE) -> 253.4 | D14: =VLOOKUP(A14, 'PAH3.DE'!$A$31:$B$1500, 2, FALSE) -> 56.02 | E14: =VLOOKUP(A14,HRMS.PA!$A$33:$B$2000,2,FALSE) -> 500.4 | F14: =VLOOKUP(A14,'.STOXX'!$A$27:$B$1500,2,FALSE) -> 357.05
A15: 43486 | B15: 100.5 | C15: =VLOOKUP(A15, LVMH.PA!$A$32:$B$2000, 2, FALSE) -> 257.25 | D15: =VLOOKUP(A15, 'PAH3.DE'!$A$31:$B$1500, 2, FALSE) -> 55.42 | E15: =VLOOKUP(A15,HRMS.PA!$A$33:$B$2000,2,FALSE) -> 501.4 | F15: =VLOOKUP(A15,'.STOXX'!$A$27:$B$1500,2,FALSE) -> 356.36
... A1274: 45289 | B1274: 305.2 | C1274: =VLOOKUP(A1274, LVMH.PA!$A$32:$B$2000, 2, FALSE) -> 733.6 | D1274: =VLOOKUP(A1274, 'PAH3.DE'!$A$31:$B$1500, 2, FALSE) -> 46.32 | E1274: =VLOOKUP(A1274,HRMS.PA!$A$33:$B$2000,2,FALSE) -> 1918.8 | F1274: =VLOOKUP(A1274,'.STOXX'!$A$27:$B$1500,2,FALSE) -> 478.99

Sheet Confronto prezzi corretto
A1: {=_xlfn.VSTACK('Confronto prezzi'!A1:F1, _xlfn._xlws.FILTER('Confronto prezzi'!A2:F1274, ISNUMBER('Confronto prezzi'!D2:D1274)))} -> Exchange Date | B1: RACE.MI | C1: LVMH.PA | D1: PAH3.DE | E1: HRMS.PA | F1: .STOXX
A2: 43467 | B2: 86.52 | C2: 253.3 | D2: 50.98 | E2: 477.6 | F2: 337.21
A3: 43468 | B3: 85.6 | C3: 243.65 | D3: 50.28 | E3: 464 | F3: 333.92
A4: 43469 | B4: 89.4 | C4: 251.15 | D4: 52.78 | E4: 477.8 | F4: 343.38
A5: 43472 | B5: 91.32 | C5: 250.7 | D5: 53.16 | E5: 472.2 | F5: 342.88
A6: 43473 | B6: 94.14 | C6: 258.55 | D6: 54.1 | E6: 479.9 | F6: 345.85
A7: 43474 | B7: 96.7 | C7: 261.55 | D7: 55.6 | E7: 491.2 | F7: 347.7
A8: 43475 | B8: 96.36 | C8: 259.15 | D8: 55.6 | E8: 489.9 | F8: 348.88
A9: 43476 | B9: 96.76 | C9: 258.3 | D9: 55.1 | E9: 496.4 | F9: 349.2
A10: 43479 | B10: 96.36 | C10: 251.7 | D10: 54.96 | E10: 488.7 | F10: 347.51
A11: 43480 | B11: 98.28 | C11: 250.8 | D11: 55.5 | E11: 494 | F11: 348.71
A12: 43481 | B12: 99.26 | C12: 248.95 | D12: 55.94 | E12: 488.9 | F12: 350.59
A13: 43482 | B13: 99.52 | C13: 246.55 | D13: 55.24 | E13: 495.7 | F13: 350.73
... A1270: 45289 | B1270: 305.2 | C1270: 733.6 | D1270: 46.32 | E1270: 1918.8 | F1270: 478.99

Sheet Confronto con indicizzazione
A1: Exchange Date | B1: RACE.MI | C1: LVMH.PA | D1: PAH3.DE | E1: HRMS.PA | F1: .STOXX
A2: 43467 | B2: 100 | C2: 100 | D2: 100 | E2: 100 | F2: 100
A3: 43468 | B3: 98.936662 | C3: 96.190288 | D3: 98.626913 | E3: 97.152429 | F3: 99.024347
A4: 43469 | B4: 103.32871 | C4: 99.151204 | D4: 103.5308 | E4: 100.04188 | F4: 101.82972
A5: 43472 | B5: 105.54785 | C5: 98.973549 | D5: 104.27619 | E5: 98.869347 | F5: 101.68144
A6: 43473 | B6: 108.80721 | C6: 102.07264 | D6: 106.12005 | E6: 100.48157 | F6: 102.5622
A7: 43474 | B7: 111.76607 | C7: 103.25701 | D7: 109.06238 | E7: 102.84757 | F7: 103.11082
A8: 43475 | B8: 111.37309 | C8: 102.30951 | D8: 109.06238 | E8: 102.57538 | F8: 103.46075
A9: 43476 | B9: 111.83541 | C9: 101.97394 | D9: 108.0816 | E9: 103.93635 | F9: 103.55565
A10: 43479 | B10: 111.37309 | C10: 99.368338 | D10: 107.80698 | E10: 102.32412 | F10: 103.05448
A11: 43480 | B11: 113.59223 | C11: 99.013028 | D11: 108.86622 | E11: 103.43384 | F11: 103.41034
A12: 43481 | B12: 114.72492 | C12: 98.282669 | D12: 109.72931 | E12: 102.366 | F12: 103.96785
A13: 43482 | B13: 115.02543 | C13: 97.335176 | D13: 108.35622 | E13: 103.78978 | F13: 104.00937
... A1270: 45289 | B1270: 352.75081 | C1270: 289.61705 | D1270: 90.85916 | E1270: 401.75879 | F1270: 142.04502

Sheet Grafico con indicizzazione

Sheet Confronto rendimenti
A1: Exchange Date | B1: Rendimenti giornalieri RACE.MI | C1: Rendimenti giornalieri LVMH.PA | D1: Rendimenti giornalieri PAH3.DE | E1: Rendimenti giornalieri HRMS.PA | F1: Rendimenti giornalieri .STOXX
A2: 43467
A3: 43468 | B3: -0.01063338 | C3: -0.038097118 | D3: -0.013730875 | E3: -0.028475712 | F3: -0.0097565315
A4: 43469 | B4: 0.044392523 | C4: 0.030781859 | D4: 0.049721559 | E4: 0.029741379 | F4: 0.028330139
A5: 43472 | B5: 0.02147651 | C5: -0.0017917579 | D5: 0.0071996969 | E5: -0.011720385 | F5: -0.0014561128
A6: 43473 | B6: 0.03088042 | C6: 0.031312325 | D6: 0.017682468 | E6: 0.01630665 | F6: 0.0086619225
A7: 43474 | B7: 0.027193542 | C7: 0.011603172 | D7: 0.027726433 | E7: 0.023546572 | F7: 0.0053491398
A8: 43475 | B8: -0.003516029 | C8: -0.0091760658 | D8: 0 | E8: -0.0026465798 | F8: 0.0033937302
A9: 43476 | B9: 0.0041511 | C9: -0.0032799537 | D9: -0.0089928058 | E9: 0.013268014 | F9: 0.00091722082
A10: 43479 | B10: -0.0041339396 | C10: -0.025551684 | D10: -0.0025408348 | E10: -0.015511684 | F10: -0.0048396334
A11: 43480 | B11: 0.01992528 | C11: -0.0035756853 | D11: 0.0098253275 | E11: 0.010845099 | F11: 0.003453138
A12: 43481 | B12: 0.00997151 | C12: -0.0073763955 | D12: 0.0079279279 | E12: -0.010323887 | F12: 0.0053912994
A13: 43482 | B13: 0.0026193834 | C13: -0.0096404901 | D13: -0.012513407 | E13: 0.013908775 | F13: 0.00039932685
A14: 43483 | B14: -0.00020096463 | C14: 0.027783411 | D14: 0.014120203 | E14: 0.0094815413 | F14: 0.018019559
... A1270: 45289 | B1270: 0.0026281209 | C1270: 0.0035567715 | D1270: -0.0019392372 | E1270: 0.0041867281 | F1270: 0.0019034471

Sheet Rendimenti RACE.MI
A1: Exchange Date | B1: RACE.MI | C1: Rendimenti giornalieri RACE.MI | D1: Rendimenti LN giornalieri RACE.MI | E1: Rendimenti LN giornalieri RACE.MI
A2: 43467 | B2: 86.52
A3: 43468 | B3: 85.6 | C3: =(B3/B2-1) -> -0.01063338 | D3: =(LN('Confronto prezzi corretto'!B3)-LN('Confronto prezzi corretto'!B2)) -> -0.010690318 | E3: Media | F3: 0.00099415749
A4: 43469 | B4: 89.4 | C4: =(B4/B3-1) -> 0.044392523 | D4: =(LN('Confronto prezzi corretto'!B4)-LN('Confronto prezzi corretto'!B3)) -> 0.043435399 | E4: Errore standard | F4: 0.00047385752
A5: 43472 | B5: 91.32 | C5: =(B5/B4-1) -> 0.02147651 | D5: =(LN('Confronto prezzi corretto'!B5)-LN('Confronto prezzi corretto'!B4)) -> 0.021249139 | E5: Mediana | F5: 0.0011016953
A6: 43473 | B6: 94.14 | C6: =(B6/B5-1) -> 0.03088042 | D6: =(LN('Confronto prezzi corretto'!B6)-LN('Confronto prezzi corretto'!B5)) -> 0.030413214 | E6: Moda | F6: 0
A7: 43474 | B7: 96.7 | C7: =(B7/B6-1) -> 0.027193542 | D7: =(LN('Confronto prezzi corretto'!B7)-LN('Confronto prezzi corretto'!B6)) -> 0.026830366 | E7: Deviazione standard | F7: 0.016873587
A8: 43475 | B8: 96.36 | C8: =(B8/B7-1) -> -0.003516029 | D8: =(LN('Confronto prezzi corretto'!B8)-LN('Confronto prezzi corretto'!B7)) -> -0.0035222247 | E8: Varianza campionaria | F8: 0.00028471792
A9: 43476 | B9: 96.76 | C9: =(B9/B8-1) -> 0.0041511 | D9: =(LN('Confronto prezzi corretto'!B9)-LN('Confronto prezzi corretto'!B8)) -> 0.004142508 | E9: Curtosi | F9: 5.4643029
A10: 43479 | B10: 96.36 | C10: =(B10/B9-1) -> -0.0041339396 | D10: =(LN('Confronto prezzi corretto'!B10)-LN('Confronto prezzi corretto'!B9)) -> -0.004142508 | E10: Asimmetria | F10: -0.0006206831
A11: 43480 | B11: 98.28 | C11: =(B11/B10-1) -> 0.01992528 | D11: =(LN('Confronto prezzi corretto'!B11)-LN('Confronto prezzi corretto'!B10)) -> 0.01972937 | E11: Intervallo | F11: 0.21278912
A12: 43481 | B12: 99.26 | C12: =(B12/B11-1) -> 0.00997151 | D12: =(LN('Confronto prezzi corretto'!B12)-LN('Confronto prezzi corretto'!B11)) -> 0.0099221225 | E12: Minimo | F12: -0.10824677
A13: 43482 | B13: 99.52 | C13: =(B13/B12-1) -> 0.0026193834 | D13: =(LN('Confronto prezzi corretto'!B13)-LN('Confronto prezzi corretto'!B12)) -> 0.0026159588 | E13: Massimo | F13: 0.10454235
A14: 43483 | B14: 99.5 | C14: =(B14/B13-1) -> -0.00020096463 | D14: =(LN('Confronto prezzi corretto'!B14)-LN('Confronto prezzi corretto'!B13)) -> -0.00020098483 | E14: Somma | F14: 1.2605917
A15: 43486 | B15: 100.5 | C15: =(B15/B14-1) -> 0.010050251 | D15: =(LN('Confronto prezzi corretto'!B15)-LN('Confronto prezzi corretto'!B14)) -> 0.010000083 | E15: Conteggio | F15: 1268
A16: 43487 | B16: 98.42 | C16: =(B16/B15-1) -> -0.020696517 | D16: =(LN('Confronto prezzi corretto'!B16)-LN('Confronto prezzi corretto'!B15)) -> -0.020913692
A17: 43488 | B17: 96.84 | C17: =(B17/B16-1) -> -0.016053648 | D17: =(LN('Confronto prezzi corretto'!B17)-LN('Confronto prezzi corretto'!B16)) -> -0.016183903
A18: 43489 | B18: 99.04 | C18: =(B18/B17-1) -> 0.022717885 | D18: =(LN('Confronto prezzi corretto'!B18)-LN('Confronto prezzi corretto'!B17)) -> 0.022463677
A19: 43490 | B19: 97.98 | C19: =(B19/B18-1) -> -0.010702746 | D19: =(LN('Confronto prezzi corretto'!B19)-LN('Confronto prezzi corretto'!B18)) -> -0.010760433
A20: 43493 | B20: 95.7 | C20: =(B20/B19-1) -> -0.023270055 | D20: =(LN('Confronto prezzi corretto'!B20)-LN('Confronto prezzi corretto'!B19)) -> -0.023545078
A21: 43494 | B21: 96.1 | C21: =(B21/B20-1) -> 0.0041797283 | D21: =(LN('Confronto prezzi corretto'!B21)-LN('Confronto prezzi corretto'!B20)) -> 0.0041710175
A22: 43495 | B22: 97.82 | C22: =(B22/B21-1) -> 0.017898023 | D22: =(LN('Confronto prezzi corretto'!B22)-LN('Confronto prezzi corretto'!B21)) -> 0.017739739
A23: 43496 | B23: 108.6 | C23: =(B23/B22-1) -> 0.11020241 | D23: =(LN('Confronto prezzi corretto'!B23)-LN('Confronto prezzi corretto'!B22)) -> 0.10454235
A24: 43497 | B24: 110.6 | C24: =(B24/B23-1) -> 0.018416206 | D24: =(LN('Confronto prezzi corretto'!B24)-LN('Confronto prezzi corretto'!B23)) -> 0.018248682
A25: 43500 | B25: 110.35 | C25: =(B25/B24-1) -> -0.0022603978 | D25: =(LN('Confronto prezzi corretto'!B25)-LN('Confronto prezzi corretto'!B24)) -> -0.0022629564
A26: 43501 | B26: 112.25 | C26: =(B26/B25-1) -> 0.017217943 | D26: =(LN('Confronto prezzi corretto'!B26)-LN('Confronto prezzi corretto'!B25)) -> 0.017071394
A27: 43502 | B27: 111.85 | C27: =(B27/B26-1) -> -0.0035634744 | D27: =(LN('Confronto prezzi corretto'!B27)-LN('Confronto prezzi corretto'!B26)) -> -0.0035698387
... A1270: 45289 | B1270: 305.2 | C1270: =(B1270/B1269-1) -> 0.0026281209 | D1270: =(LN('Confronto prezzi corretto'!B1270)-LN('Confronto prezzi corretto'!B1269)) -> 0.0026246734

Sheet Analisi rendimenti RACE.MI

Sheet Grafico media mobile

Sheet Volatilità
A1: Exchange Date | B1: RACE.MI | C1: Rendimenti giornalieri RACE.MI | D1: LN Rendimenti giornalieri RACE.MI | E1: Volatilità a 20 gg | F1: Volatilità a 20 gg - annualizzata | K1: Exchange Date | L1: .STOXX | M1: Rendimenti giornalieri .STOXX | N1: Rendimenti LN giornalieri .STOXX | O1: Volatilità a 20 gg | P1: Volatilità a 20 gg - annualizzata
A2: 43467 | B2: 86.52 | K2: 43467 | L2: 337.21
A3: 43468 | B3: 85.6 | C3: -0.01063338 | D3: -0.010690318 | K3: 43468 | L3: 333.92 | M3: -0.0097565315 | N3: =(LN(L3)-LN(L2)) -> -0.0098044383
A4: 43469 | B4: 89.4 | C4: 0.044392523 | D4: 0.043435399 | K4: 43469 | L4: 343.38 | M4: 0.028330139 | N4: =(LN(L4)-LN(L3)) -> 0.027936262
A5: 43472 | B5: 91.32 | C5: 0.02147651 | D5: 0.021249139 | K5: 43472 | L5: 342.88 | M5: -0.0014561128 | N5: =(LN(L5)-LN(L4)) -> -0.0014571739
A6: 43473 | B6: 94.14 | C6: 0.03088042 | D6: 0.030413214 | K6: 43473 | L6: 345.85 | M6: 0.0086619225 | N6: =(LN(L6)-LN(L5)) -> 0.0086246233
A7: 43474 | B7: 96.7 | C7: 0.027193542 | D7: 0.026830366 | K7: 43474 | L7: 347.7 | M7: 0.0053491398 | N7: =(LN(L7)-LN(L6)) -> 0.005334884
A8: 43475 | B8: 96.36 | C8: -0.003516029 | D8: -0.0035222247 | K8: 43475 | L8: 348.88 | M8: 0.0033937302 | N8: =(LN(L8)-LN(L7)) -> 0.0033879845
A9: 43476 | B9: 96.76 | C9: 0.0041511 | D9: 0.004142508 | K9: 43476 | L9: 349.2 | M9: 0.00091722082 | N9: =(LN(L9)-LN(L8)) -> 0.00091680043
A10: 43479 | B10: 96.36 | C10: -0.0041339396 | D10: -0.004142508 | K10: 43479 | L10: 347.51 | M10: -0.0048396334 | N10: =(LN(L10)-LN(L9)) -> -0.0048513824
A11: 43480 | B11: 98.28 | C11: 0.01992528 | D11: 0.01972937 | K11: 43480 | L11: 348.71 | M11: 0.003453138 | N11: =(LN(L11)-LN(L10)) -> 0.0034471896
A12: 43481 | B12: 99.26 | C12: 0.00997151 | D12: 0.0099221225 | K12: 43481 | L12: 350.59 | M12: 0.0053912994 | N12: =(LN(L12)-LN(L11)) -> 0.0053768183
A13: 43482 | B13: 99.52 | C13: 0.0026193834 | D13: 0.0026159588 | K13: 43482 | L13: 350.73 | M13: 0.00039932685 | N13: =(LN(L13)-LN(L12)) -> 0.00039924714
A14: 43483 | B14: 99.5 | C14: -0.00020096463 | D14: -0.00020098483 | K14: 43483 | L14: 357.05 | M14: 0.018019559 | N14: =(LN(L14)-LN(L13)) -> 0.017859131
... A21: 43494 | B21: 96.1 | C21: 0.0041797283 | D21: 0.0041710175 | K21: 43494 | L21: 357.23 | M21: 0.0080422146 | N21: =(LN(L21)-LN(L20)) -> 0.0080100483
A22: 43495 | B22: 97.82 | C22: 0.017898023 | D22: 0.017739739 | E22: =STDEVA(D3:D22) -> 0.018051585 | F22: =E22*SQRT(252) -> 0.28656002 | K22: 43495 | L22: 358.51 | M22: 0.0035831257 | N22: =(LN(L22)-LN(L21)) -> 0.0035767216 | O22: =STDEVA(N3:N22) -> 0.0086440905 | P22: =O22*SQRT(252) -> 0.13722068
A23: 43496 | B23: 108.6 | C23: 0.11020241 | D23: 0.10454235 | E23: =STDEVA(D4:D23) -> 0.028029783 | F23: =E23*SQRT(252) -> 0.44495901 | K23: 43496 | L23: 358.67 | M23: 0.0004462916 | N23: =(LN(L23)-LN(L22)) -> 0.00044619204 | O23: =STDEVA(N4:N23) -> 0.0081296022 | P23: =O23*SQRT(252) -> 0.12905343
A24: 43497 | B24: 110.6 | C24: 0.018416206 | D24: 0.018248682 | E24: =STDEVA(D5:D24) -> 0.027088332 | F24: =E24*SQRT(252) -> 0.43001393 | K24: 43497 | L24: 359.71 | M24: 0.0028996013 | N24: =(LN(L24)-LN(L23)) -> 0.0028954056 | O24: =STDEVA(N5:N24) -> 0.0057645012 | P24: =O24*SQRT(252) -> 0.091508619
A25: 43500 | B25: 110.35 | C25: -0.0022603978 | D25: -0.0022629564 | E25: =STDEVA(D6:D25) -> 0.02711386 | F25: =E25*SQRT(252) -> 0.43041918 | K25: 43500 | L25: 359.92 | M25: 0.00058380362 | N25: =(LN(L25)-LN(L24)) -> 0.00058363327 | O25: =STDEVA(N6:N25) -> 0.0057118867 | P25: =O25*SQRT(252) -> 0.09067339
A26: 43501 | B26: 112.25 | C26: 0.017217943 | D26: 0.017071394 | E26: =STDEVA(D7:D26) -> 0.02673277 | F26: =E26*SQRT(252) -> 0.42436957 | K26: 43501 | L26: 364.99 | M26: 0.014086464 | N26: =(LN(L26)-LN(L25)) -> 0.013988171 | O26: =STDEVA(N7:N26) -> 0.0061289644 | P26: =O26*SQRT(252) -> 0.097294294
A27: 43502 | B27: 111.85 | C27: -0.0035634744 | D27: -0.0035698387 | E27: =STDEVA(D8:D27) -> 0.02651685 | F27: =E27*SQRT(252) -> 0.42094195 | K27: 43502 | L27: 365.52 | M27: 0.0014520946 | N27: =(LN(L27)-LN(L26)) -> 0.0014510413 | O27: =STDEVA(N8:N27) -> 0.0061023311 | P27: =O27*SQRT(252) -> 0.096871503
A28: 43503 | B28: 109 | C28: -0.025480554 | D28: -0.025810806 | E28: =STDEVA(D9:D28) -> 0.027446672 | F28: =E28*SQRT(252) -> 0.43570241 | K28: 43503 | L28: 360.08 | M28: -0.014882907 | N28: =(LN(L28)-LN(L27)) -> -0.014994768 | O28: =STDEVA(N9:N28) -> 0.0072397935 | P28: =O28*SQRT(252) -> 0.11492816
A29: 43504 | B29: 108.95 | C29: -0.0004587156 | D29: -0.00045882084 | E29: =STDEVA(D10:D29) -> 0.027483758 | F29: =E29*SQRT(252) -> 0.43629113 | K29: 43504 | L29: 358.07 | M29: -0.0055820929 | N29: =(LN(L29)-LN(L28)) -> -0.005597731 | O29: =STDEVA(N10:N29) -> 0.007415611 | P29: =O29*SQRT(252) -> 0.11771917
A30: 43507 | B30: 109.55 | C30: 0.0055071134 | D30: 0.0054920047 | E30: =STDEVA(D11:D30) -> 0.027382115 | F30: =E30*SQRT(252) -> 0.43467759 | K30: 43507 | L30: 361.12 | M30: 0.0085178876 | N30: =(LN(L30)-LN(L29)) -> 0.0084818151 | O30: =STDEVA(N11:N30) -> 0.0074371275 | P30: =O30*SQRT(252) -> 0.11806074
A31: 43508 | B31: 111.1 | C31: 0.014148791 | D31: 0.014049631 | E31: =STDEVA(D12:D31) -> 0.027265961 | F31: =E31*SQRT(252) -> 0.43283372 | K31: 43508 | L31: 362.78 | M31: 0.0045968099 | N31: =(LN(L31)-LN(L30)) -> 0.0045862769 | O31: =STDEVA(N12:N31) -> 0.0074537747 | P31: =O31*SQRT(252) -> 0.118325
A32: 43509 | B32: 110.75 | C32: -0.003150315 | D32: -0.0031552877 | E32: =STDEVA(D13:D32) -> 0.027326986 | F32: =E32*SQRT(252) -> 0.43380245 | K32: 43509 | L32: 364.97 | M32: 0.0060367165 | N32: =(LN(L32)-LN(L31)) -> 0.0060185685 | O32: =STDEVA(N13:N32) -> 0.0074705396 | P32: =O32*SQRT(252) -> 0.11859114
A33: 43510 | B33: 110.35 | C33: -0.0036117381 | D33: -0.0036182762 | E33: =STDEVA(D14:D33) -> 0.027396801 | F33: =E33*SQRT(252) -> 0.43491074 | K33: 43510 | L33: 363.8 | M33: -0.0032057429 | N33: =(LN(L33)-LN(L32)) -> -0.0032108923 | O33: =STDEVA(N14:N33) -> 0.0075546465 | P33: =O33*SQRT(252) -> 0.11992629
... A1270: 45289 | B1270: 305.2 | C1270: 0.0026281209 | D1270: 0.0026246734 | E1270: =STDEVA(D1251:D1270) -> 0.013440484 | F1270: =E1270*SQRT(252) -> 0.21336107 | K1270: 45289 | L1270: 478.99 | M1270: 0.0019034471 | N1270: =(LN(L1270)-LN(L1269)) -> 0.0019016379 | O1270: =STDEVA(N1251:N1270) -> 0.003782538 | P1270: =O1270*SQRT(252) -> 0.06004593

Sheet Grafico volatilità a 20 gg

Sheet Grafico volatilità comparata

Sheet Statistiche descrittive 
A1: Rendimenti LN giornalieri RACE.MI
A3: Media | B3: 0.00099415749
A4: Errore standard | B4: 0.00047385752
A5: Mediana | B5: 0.0011016953
A6: Moda | B6: 0
A7: Deviazione standard | B7: 0.016873587
A8: Varianza campionaria | B8: 0.00028471792
A9: Curtosi | B9: 5.4643029
A10: Asimmetria | B10: -0.0006206831
A11: Intervallo | B11: 0.21278912
A12: Minimo | B12: -0.10824677
A13: Massimo | B13: 0.10454235
A14: Somma | B14: 1.2605917
A15: Conteggio | B15: 1268
